<!-- ///////////////////////////////////////////////////////////////////////////////////////////////////////////////////// -->

    <joint name="shoulder_pan_joint1" type="revolute">
        <parent link="base_link"/>
        <child link="shoulder_pan_link"/>
        <origin xyz="0 0 0.05" rpy="0 ${M_PI/2} ${M_PI*0}" />
        <axis xyz="-1 0 0" />
        <limit effort="300" velocity="1" lower="-2.61799387799" upper="1.98394848567"/>
        <dynamics damping="50" friction="1"/>
    </joint>


<!-- ///////////////////////////////////////////////////////////////////////////////////////////////////////////////////// -->

  <!-- SHOULDER PAN LINK -->
    <link name="shoulder_pan_link" >
        <visual>
            <origin xyz="0 0 0" rpy="0 ${M_PI/2} 0" />
            <geometry>

                <cylinder radius="${shoulder_pan_width}" length="${shoulder_pan_len}"/>

            </geometry>
            <material name="Red" />
        </visual>
        <collision>
            <origin xyz="0 0 0" rpy="0 ${M_PI/2} 0" />
            <geometry>
                <cylinder radius="${shoulder_pan_width}" length="${shoulder_pan_len}"/>
            </geometry>
        </collision>
        <xacro:inertial_matrix mass="1"/>
    </link>

    <gazebo reference="shoulder_pan_link">
        <material>Gazebo/Red</material>
    </gazebo>

    <joint name="shoulder_pitch_joint" type="revolute">
        <parent link="shoulder_pan_link"/>
        <child link="shoulder_pitch_link"/>
        <origin xyz="-0.041 0.0021 0.0" rpy="-${M_PI/2} 0 ${M_PI/2}" />
        <axis xyz="1 0 0" />
        <limit effort="300" velocity="1" lower="-1.19962513147" upper="1.89994105047" />
        <dynamics damping="50" friction="1"/>
    </joint>

<!-- ///////////////////////////////////////////////////////////////////////////////////////////////////////////////////// -->
  <!-- SHOULDER PITCH LINK -->
    <link name="shoulder_pitch_link" >

        <visual>
            <origin xyz="-0.002 0 0.04" rpy="0 ${M_PI/2} 0" />
            <geometry>
                <box size="${shoulder_pitch_len} ${shoulder_pitch_width} ${shoulder_pitch_height}" />
            </geometry>
            <material name="White" />
        </visual>

        <collision>
            <origin xyz="-0.002 0 0.04" rpy="0 ${M_PI/2} 0" />
            <geometry>
                <box size="${shoulder_pitch_len} ${shoulder_pitch_width} ${shoulder_pitch_height}" />
            </geometry>
        </collision>
        <xacro:inertial_matrix mass="1"/>
    </link>

    <gazebo reference="shoulder_pitch_link">
        <material>Gazebo/White</material>
    </gazebo>

    <joint name="elbow_roll_joint" type="revolute">
        <parent link="shoulder_pitch_link"/>
        <child link="elbow_roll_link"/>
        <origin xyz="-0.002 0 0.1206" rpy="${M_PI} ${M_PI/2} 0" />
        <axis xyz="-1 0 0" />
        <limit effort="300" velocity="1" lower="-2.61799387799" upper="0.705631162427" />
        <dynamics damping="50" friction="1"/>
    </joint>

<!-- ///////////////////////////////////////////////////////////////////////////////////////////////////////////////////// -->
    <!-- ELBOW ROLL LINK -->
    <link name="elbow_roll_link" >
        <visual>
            <origin xyz="-0.015 0.0 -0.0" rpy="0 ${M_PI/2} 0" />
            <geometry>

                <cylinder radius="${elbow_roll_width}" length="${elbow_roll_len}"/>

            </geometry>
            <material name="Black" />
        </visual>

        <collision>
            <origin xyz="-0.015 0.0 -0.0" rpy="0 ${M_PI/2} 0" />
            <geometry>
                <cylinder radius="${elbow_roll_width}" length="${elbow_roll_len}"/>
            </geometry>
        </collision>
        <xacro:inertial_matrix mass="1"/>
    </link>

    <gazebo reference="elbow_roll_link">
        <material>Gazebo/Black</material>
    </gazebo>

    <joint name="elbow_pitch_joint" type="revolute">
        <parent link="elbow_roll_link"/>
        <child link="elbow_pitch_link"/>
        <origin xyz="-0.035 0 0.0" rpy="0.055 ${M_PI/2} 0" />
        <axis xyz="1 0 0" />
        <limit effort="300" velocity="1" lower="-1.5953400194" upper="1.93281579274" />
        <dynamics damping="50" friction="1"/>
    </joint>

<!-- ///////////////////////////////////////////////////////////////////////////////////////////////////////////////////// -->

    <!-- ELBOW PITCH LINK -->
    <link name="elbow_pitch_link" >
        <visual>
            <origin xyz="0 0 -0.12" rpy="0 ${M_PI/2} 0" />
            <geometry>
            <box size="${elbow_pitch_len} ${elbow_pitch_width} ${elbow_pitch_height}" />
            </geometry>
            <material name="Red" />
        </visual>

        <collision>
            <origin xyz="0 0 -0.12" rpy="0 ${M_PI/2} 0" />
            <geometry>
            <box size="${elbow_pitch_len} ${elbow_pitch_width} ${elbow_pitch_height}" />
            </geometry>
        </collision>
        <xacro:inertial_matrix mass="1"/>
    </link>

    <gazebo reference="elbow_pitch_link">
        <material>Gazebo/Red</material>
    </gazebo>

    <joint name="wrist_roll_joint" type="revolute">
        <parent link="elbow_pitch_link"/>
        <child link="wrist_roll_link"/>
        <origin xyz="0.0 0.0081 -.248" rpy="0 ${M_PI/2} ${M_PI}" />
        <axis xyz="1 0 0" />
        <limit effort="300" velocity="1" lower="-2.61799387799" upper="2.6128806087" />
        <dynamics damping="50" friction="1"/>
    </joint>

<!-- ///////////////////////////////////////////////////////////////////////////////////////////////////////////////////// -->

    <!-- WRIST ROLL LINK -->
    <link name="wrist_roll_link" >
        <visual>
            <origin xyz="0 0 0" rpy="0 ${M_PI/2} 0" />
            <geometry>

                <cylinder radius="${elbow_roll_width}" length="${elbow_roll_len}"/>

            </geometry>
            <material name="Black" />
        </visual>

        <collision>
            <origin xyz="0 0 0" rpy="0 ${M_PI/2} 0" />
            <geometry>
                <cylinder radius="${elbow_roll_width}" length="${elbow_roll_len}"/>
            </geometry>
        </collision>
        <xacro:inertial_matrix mass="1"/>
    </link>

    <gazebo reference="wrist_roll_link">
        <material>Gazebo/Black</material>
    </gazebo>

    <joint name="wrist_pitch_joint" type="revolute">
        <parent link="wrist_roll_link"/>
        <child link="wrist_pitch_link"/>
        <origin xyz="0.0 0.0 0.0001" rpy="0 ${M_PI/2} 0" />
        <axis xyz="1 0 0" />
        <limit effort="300" velocity="1" lower="-1.5953400194" upper="1.98394848567" />
        <dynamics damping="50" friction="1"/>
    </joint>


<!-- ///////////////////////////////////////////////////////////////////////////////////////////////////////////////////// -->
    <!-- WRIST PITCH LINK -->
    <link name="wrist_pitch_link">
        <visual>
            <origin xyz="0 0 0.04" rpy="0 ${M_PI/2} 0" />
            <geometry>

                <box size="${wrist_pitch_len} ${wrist_pitch_width} ${wrist_pitch_height}" />

            </geometry>
            <material name="White" />
        </visual>

        <collision>
            <origin xyz="0 0 0.04 " rpy="0 ${M_PI/2} 0" />
            <geometry>
                <box size="${wrist_pitch_len} ${wrist_pitch_width} ${wrist_pitch_height}" />
            </geometry>
        </collision>
        <xacro:inertial_matrix mass="1"/>

    </link>

    <gazebo reference="wrist_pitch_link">
        <material>Gazebo/White</material>
    </gazebo>

    <joint name="gripper_roll_joint" type="revolute">
        <parent link="wrist_pitch_link"/>
        <child link="gripper_roll_link"/>
        <origin xyz="0 0 0.080" rpy="${1.5*M_PI} -${.5*M_PI} 0" />
        <axis xyz="1 0 0" />
        <limit effort="300" velocity="1" lower="-2.61799387799" upper="2.6128806087" />
        <dynamics damping="50" friction="1"/>
    </joint>

<!-- ///////////////////////////////////////////////////////////////////////////////////////////////////////////////////// -->

    <!-- GRIPPER ROLL LINK -->
    <link name="gripper_roll_link">
        <visual>
            <origin xyz="0 0 0" rpy="0 ${M_PI/2} 0" />
            <geometry>

                <cylinder radius="${gripper_roll_width}" length="${gripper_roll_len}"/>

            </geometry>
            <material name="Red" />
        </visual>

        <collision>
            <origin xyz="0 0 0" rpy="0 ${M_PI/2} 0" />
            <geometry>
                <cylinder radius="${gripper_roll_width}" length="${gripper_roll_len}"/>
            </geometry>
        </collision>
        <xacro:inertial_matrix mass="1"/>

    </link>

    <gazebo reference="gripper_roll_link">
        <material>Gazebo/Red</material>
    </gazebo>

    <joint name="finger_joint1" type="prismatic">
        <parent link="gripper_roll_link"/>
        <child link="gripper_finger_link1"/>
        <origin xyz="0.0 0 0" />
        <axis xyz="0 1 0" />
            <limit effort="100" lower="0" upper="0.03" velocity="1.0"/>


            <safety_controller k_position="20"
                                k_velocity="20"
                                soft_lower_limit="${-0.15 }"
                                soft_upper_limit="${ 0.0 }"/>


        <dynamics damping="50" friction="1"/>
    </joint>


<!-- ///////////////////////////////////////////////////////////////////////////////////////////////////////////////////// -->

    <!-- LEFT GRIPPER AFT LINK -->
    <link name="gripper_finger_link1">
        <visual>
            <origin xyz="0.04 -0.03 0"/>
            <geometry>

                <box size="${left_gripper_len} ${left_gripper_width} ${left_gripper_height}" />

            </geometry>
            <material name="White" />
        </visual>
        <xacro:inertial_matrix mass="1"/>
    </link>

    <gazebo reference="gripper_finger_link1">
        <material>Gazebo/White</material>
    </gazebo>

    <!-- Joint between Wrist roll and finger 2 -->

    <joint name="finger_joint2" type="prismatic">
        <parent link="gripper_roll_link"/>
        <child link="gripper_finger_link2"/>
        <origin xyz="0.0 0 0" />
        <axis xyz="0 1 0" />
        <limit effort="1" lower="-0.03" upper="0" velocity="1.0"/>
        <dynamics damping="50" friction="1"/>
    </joint> 

<!-- ///////////////////////////////////////////////////////////////////////////////////////////////////////////////////// -->

    <!-- RIGHT GRIPPER AFT LINK -->
    <link name="gripper_finger_link2">
        <visual>
            <origin xyz="0.04 0.03 0"/>
            <geometry>
                <box size="${right_gripper_len} ${right_gripper_width} ${right_gripper_height}" />
            </geometry>
            <material name="White" />
        </visual>
        <xacro:inertial_matrix mass="1"/>
    </link>

    <gazebo reference="gripper_finger_link2">
        <material>Gazebo/White</material>
    </gazebo>


<!-- ///////////////////////////////////////////////////////////////////////////////////////////////////////////////////// -->

    <!-- Define RGB-D sensor -->  
    <!-- <xacro:xtion_pro_live name="rgbd_camera" parent="base">
        <origin xyz="0.1 0.0 0.9" rpy="${0.0 * deg_to_rad} ${70.0 * deg_to_rad} ${0.0 * deg_to_rad}"/>
        <origin xyz="0 0 0" rpy="${-90 * deg_to_rad} ${0 * deg_to_rad} ${-90 * deg_to_rad}" />
    </xacro:xtion_pro_live> -->


    <!-- Transmissions for ROS Control -->
    <!-- <xacro:transmission_block joint_name="shoulder_pan_joint1"/>
    <xacro:transmission_block joint_name="shoulder_pitch_joint"/>
    <xacro:transmission_block joint_name="elbow_roll_joint"/>
    <xacro:transmission_block joint_name="elbow_pitch_joint"/>
    <xacro:transmission_block joint_name="wrist_roll_joint"/>
    <xacro:transmission_block joint_name="wrist_pitch_joint"/>
    <xacro:transmission_block joint_name="gripper_roll_joint"/>
    <xacro:transmission_block joint_name="finger_joint1"/>
    <xacro:transmission_block joint_name="finger_joint2"/> -->


    <!-- ros_control plugin -->
    <!-- <gazebo>
        <plugin name="gazebo_ros_control" filename="libgazebo_ros_control.so">
            <robotNamespace>/seven_dof_arm</robotNamespace>
        </plugin>
    </gazebo> -->