<?xml version="1.0" ?>
<!-- =================================================================================== -->
<!-- |    This document was autogenerated by xacro from /home/abhilinux20/ros_learning_ws/src/a05_seven_dof_arm/urdf/seven_dof_arm.xacro | -->
<!-- |    EDITING THIS FILE BY HAND IS NOT RECOMMENDED                                 | -->
<!-- =================================================================================== -->
<robot name="seven_dof_arm">
    <!-- Include materials -->
    <material name="Black">
        <color rgba="0.0 0.0 0.0 1.0" />
    </material>
    <material name="Red">
        <color rgba="0.8 0.0 0.0 1.0" />
    </material>
    <material name="White">
        <color rgba="1.0 1.0 1.0 1.0" />
    </material>
    <!-- ///////////////////////////////////////////////////////////////////////////////////////////////////////////////////// -->
    <!-- BASE LINK -->
    <link name="base_link">
        <visual>
            <origin rpy="0 0 0" xyz="0 0 0" />
            <!-- rotate PI/2 -->
            <geometry>
                <box size="0.1 0.1 0.1" />
            </geometry>
            <material name="White" />
        </visual>
        <collision>
            <origin rpy="0 0 0" xyz="0 0 0" />
            <!-- rotate PI/2 -->
            <geometry>
                <box size="0.1 0.1 0.1" />
            </geometry>
        </collision>
        <inertial>
            <mass value="1" />
            <inertia ixx="1.0" ixy="0.0" ixz="0.0" iyy="0.5" iyz="0.0" izz="1.0" />
            <origin xyz="0 0 0" rpy="0 0 0" />
        </inertial>
    </link>
    <gazebo reference="base_link">
        <material>Gazebo/White</material>
        <plugin name="gazebo_ros_control" filename="libgazebo_ros_control.so">
            <robotNamespace>/</robotNamespace>
        </plugin>
    </gazebo>
    <!-- BOTTOM FIXED LINK 
This link is the base of the arm in which arm is placed -->
    <!-- ///////////////////////////////////////////////////////////////////////////////////////////////////////////////////// -->
    <joint name="bottom_joint" type="fixed">
        <origin rpy="0 0 0" xyz="0 0 0" />
        <parent link="base_link" />
        <child link="bottom_link" />
    </joint>
    <!-- bottom link -->
    <link name="bottom_link">
        <visual>
            <origin rpy="0 0 0" xyz=" 0 0 -0.04" />
            <geometry>
                <box size="1 1 0.02" />
            </geometry>
            <material name="Black" />
        </visual>
        <collision>
            <origin rpy="0 0 0" xyz=" 0 0 -0.04" />
            <geometry>
                <box size="1 1 0.02" />
            </geometry>
        </collision>
        <inertial>
            <mass value="0.1" />
            <origin xyz="0 0 0" rpy="0 0 0" />
            <inertia ixx="0.03" iyy="0.03" izz="0.03" ixy="0.0" ixz="0.0" iyz="0.0" />
        </inertial>
    </link>
    <gazebo reference="bottom_link">
        <material>Gazebo/White</material>
    </gazebo>
    <!-- ///////////////////////////////////////////////////////////////////////////////////////////////////////////////////// -->
    <joint name="shoulder_pan_joint" type="revolute">
        <parent link="base_link" />
        <child link="shoulder_pan_link" />
        <origin rpy="0 1.570795 0.0" xyz="0 0 0.05" />
        <axis xyz="-1 0 0" />
        <limit effort="300" lower="-2.61799387799" upper="1.98394848567" velocity="1" />
        <dynamics damping="50" friction="1" />
    </joint>
    <!-- ///////////////////////////////////////////////////////////////////////////////////////////////////////////////////// -->
    <!-- SHOULDER PAN LINK -->
    <link name="shoulder_pan_link">
        <visual>
            <origin rpy="0 1.570795 0" xyz="0 0 0" />
            <geometry>
                <cylinder length="0.08" radius="0.04" />
            </geometry>
            <material name="Red" />
        </visual>
        <collision>
            <origin rpy="0 1.570795 0" xyz="0 0 0" />
            <geometry>
                <cylinder length="0.08" radius="0.04" />
            </geometry>
        </collision>
        <inertial>
            <mass value="1" />
            <inertia ixx="1.0" ixy="0.0" ixz="0.0" iyy="0.5" iyz="0.0" izz="1.0" />
            <origin xyz="0 0 0" rpy="0 0 0" />
        </inertial>
    </link>
    <gazebo reference="shoulder_pan_link">
        <material>Gazebo/Red</material>
    </gazebo>
    <joint name="shoulder_pitch_joint" type="revolute">
        <parent link="shoulder_pan_link" />
        <child link="shoulder_pitch_link" />
        <origin rpy="-1.570795 0 1.570795" xyz="-0.041 0.0021 0.0" />
        <axis xyz="1 0 0" />
        <limit effort="300" lower="-1.19962513147" upper="1.89994105047" velocity="1" />
        <dynamics damping="50" friction="1" />
    </joint>
    <!-- ///////////////////////////////////////////////////////////////////////////////////////////////////////////////////// -->
    <!-- SHOULDER PITCH LINK -->
    <link name="shoulder_pitch_link">
        <visual>
            <origin rpy="0 1.570795 0" xyz="-0.002 0 0.04" />
            <geometry>
                <box size="0.14 0.04 0.04" />
            </geometry>
            <material name="White" />
        </visual>
        <collision>
            <origin rpy="0 1.570795 0" xyz="-0.002 0 0.04" />
            <geometry>
                <box size="0.14 0.04 0.04" />
            </geometry>
        </collision>
        <inertial>
            <mass value="1" />
            <inertia ixx="1.0" ixy="0.0" ixz="0.0" iyy="0.5" iyz="0.0" izz="1.0" />
            <origin xyz="0 0 0" rpy="0 0 0" />
        </inertial>
    </link>
    <gazebo reference="shoulder_pitch_link">
        <material>Gazebo/White</material>
    </gazebo>
    <joint name="elbow_roll_joint" type="revolute">
        <parent link="shoulder_pitch_link" />
        <child link="elbow_roll_link" />
        <origin rpy="3.14159 1.570795 0" xyz="-0.002 0 0.1206" />
        <axis xyz="-1 0 0" />
        <limit effort="300" lower="-2.61799387799" upper="0.705631162427" velocity="1" />
        <dynamics damping="50" friction="1" />
    </joint>
    <!-- ///////////////////////////////////////////////////////////////////////////////////////////////////////////////////// -->
    <!-- ELBOW ROLL LINK -->
    <link name="elbow_roll_link">
        <visual>
            <origin rpy="0 1.570795 0" xyz="-0.015 0.0 -0.0" />
            <geometry>
                <cylinder length="0.06" radius="0.02" />
            </geometry>
            <material name="Black" />
        </visual>
        <collision>
            <origin rpy="0 1.570795 0" xyz="-0.015 0.0 -0.0" />
            <geometry>
                <cylinder length="0.06" radius="0.02" />
            </geometry>
        </collision>
        <inertial>
            <mass value="1" />
            <inertia ixx="1.0" ixy="0.0" ixz="0.0" iyy="0.5" iyz="0.0" izz="1.0" />
            <origin xyz="0 0 0" rpy="0 0 0" />
        </inertial>
    </link>
    <gazebo reference="elbow_roll_link">
        <material>Gazebo/Black</material>
    </gazebo>
    <joint name="elbow_pitch_joint" type="revolute">
        <parent link="elbow_roll_link" />
        <child link="elbow_pitch_link" />
        <origin rpy="0.055 1.570795 0" xyz="-0.035 0 0.0" />
        <axis xyz="1 0 0" />
        <limit effort="300" lower="-1.5953400194" upper="1.93281579274" velocity="1" />
        <dynamics damping="50" friction="1" />
    </joint>
    <!-- ///////////////////////////////////////////////////////////////////////////////////////////////////////////////////// -->
    <!-- ELBOW PITCH LINK -->
    <link name="elbow_pitch_link">
        <visual>
            <origin rpy="0 1.570795 0" xyz="0 0 -0.12" />
            <geometry>
                <box size="0.22 0.04 0.04" />
            </geometry>
            <material name="Red" />
        </visual>
        <collision>
            <origin rpy="0 1.570795 0" xyz="0 0 -0.12" />
            <geometry>
                <box size="0.22 0.04 0.04" />
            </geometry>
        </collision>
        <inertial>
            <mass value="1" />
            <inertia ixx="1.0" ixy="0.0" ixz="0.0" iyy="0.5" iyz="0.0" izz="1.0" />
            <origin xyz="0 0 0" rpy="0 0 0" />
        </inertial>
    </link>
    <gazebo reference="elbow_pitch_link">
        <material>Gazebo/Red</material>
    </gazebo>
    <joint name="wrist_roll_joint" type="revolute">
        <parent link="elbow_pitch_link" />
        <child link="wrist_roll_link" />
        <origin rpy="0 1.570795 3.14159" xyz="0.0 0.0081 -.248" />
        <axis xyz="1 0 0" />
        <limit effort="300" lower="-2.61799387799" upper="2.6128806087" velocity="1" />
        <dynamics damping="50" friction="1" />
    </joint>
    <!-- ///////////////////////////////////////////////////////////////////////////////////////////////////////////////////// -->
    <!-- WRIST ROLL LINK -->
    <link name="wrist_roll_link">
        <visual>
            <origin rpy="0 1.570795 0" xyz="0 0 0" />
            <geometry>
                <cylinder length="0.06" radius="0.02" />
            </geometry>
            <material name="Black" />
        </visual>
        <collision>
            <origin rpy="0 1.570795 0" xyz="0 0 0" />
            <geometry>
                <cylinder length="0.06" radius="0.02" />
            </geometry>
        </collision>
        <inertial>
            <mass value="1" />
            <inertia ixx="1.0" ixy="0.0" ixz="0.0" iyy="0.5" iyz="0.0" izz="1.0" />
            <origin xyz="0 0 0" rpy="0 0 0" />
        </inertial>
    </link>
    <gazebo reference="wrist_roll_link">
        <material>Gazebo/Black</material>
    </gazebo>
    <joint name="wrist_pitch_joint" type="revolute">
        <parent link="wrist_roll_link" />
        <child link="wrist_pitch_link" />
        <origin rpy="0 1.570795 0" xyz="0.0 0.0 0.0001" />
        <axis xyz="1 0 0" />
        <limit effort="300" lower="-1.5953400194" upper="1.98394848567" velocity="1" />
        <dynamics damping="50" friction="1" />
    </joint>
    <!-- ///////////////////////////////////////////////////////////////////////////////////////////////////////////////////// -->
    <!-- WRIST PITCH LINK -->
    <link name="wrist_pitch_link">
        <visual>
            <origin rpy="0 1.570795 0" xyz="0 0 0.04" />
            <geometry>
                <box size="0.06 0.04 0.04" />
            </geometry>
            <material name="White" />
        </visual>
        <collision>
            <origin rpy="0 1.570795 0" xyz="0 0 0.04 " />
            <geometry>
                <box size="0.06 0.04 0.04" />
            </geometry>
        </collision>
        <inertial>
            <mass value="1" />
            <inertia ixx="1.0" ixy="0.0" ixz="0.0" iyy="0.5" iyz="0.0" izz="1.0" />
            <origin xyz="0 0 0" rpy="0 0 0" />
        </inertial>
    </link>
    <gazebo reference="wrist_pitch_link">
        <material>Gazebo/White</material>
    </gazebo>
    <joint name="gripper_roll_joint" type="revolute">
        <parent link="wrist_pitch_link" />
        <child link="gripper_roll_link" />
        <origin rpy="4.712384999999999 -1.570795 0" xyz="0 0 0.080" />
        <axis xyz="1 0 0" />
        <limit effort="300" lower="-2.61799387799" upper="2.6128806087" velocity="1" />
        <dynamics damping="50" friction="1" />
    </joint>
    <!-- ///////////////////////////////////////////////////////////////////////////////////////////////////////////////////// -->
    <!-- GRIPPER ROLL LINK -->
    <link name="gripper_roll_link">
        <visual>
            <origin rpy="0 1.570795 0" xyz="0 0 0" />
            <geometry>
                <cylinder length="0.02" radius="0.04" />
            </geometry>
            <material name="Red" />
        </visual>
        <collision>
            <origin rpy="0 1.570795 0" xyz="0 0 0" />
            <geometry>
                <cylinder length="0.02" radius="0.04" />
            </geometry>
        </collision>
        <inertial>
            <mass value="1" />
            <inertia ixx="1.0" ixy="0.0" ixz="0.0" iyy="0.5" iyz="0.0" izz="1.0" />
            <origin xyz="0 0 0" rpy="0 0 0" />
        </inertial>
    </link>
    <gazebo reference="gripper_roll_link">
        <material>Gazebo/Red</material>
    </gazebo>
    <joint name="finger_joint1" type="prismatic">
        <parent link="gripper_roll_link" />
        <child link="gripper_finger_link1" />
        <origin xyz="0.0 0 0" />
        <axis xyz="0 1 0" />
        <limit effort="100" lower="0" upper="0.03" velocity="1.0" />
        <safety_controller k_position="20" k_velocity="20" soft_lower_limit="-0.15" soft_upper_limit="0.0" />
        <dynamics damping="50" friction="1" />
    </joint>
    <!-- ///////////////////////////////////////////////////////////////////////////////////////////////////////////////////// -->
    <!-- LEFT GRIPPER AFT LINK -->
    <link name="gripper_finger_link1">
        <visual>
            <origin xyz="0.04 -0.03 0" />
            <geometry>
                <box size="0.08 0.01 0.01" />
            </geometry>
            <material name="White" />
        </visual>
        <inertial>
            <mass value="1" />
            <inertia ixx="1.0" ixy="0.0" ixz="0.0" iyy="0.5" iyz="0.0" izz="1.0" />
        </inertial>
    </link>
    <gazebo reference="gripper_finger_link1">
        <material>Gazebo/White</material>
    </gazebo>
    <!-- Joint between Wrist roll and finger 2 -->
    <joint name="finger_joint2" type="prismatic">
        <parent link="gripper_roll_link" />
        <child link="gripper_finger_link2" />
        <origin xyz="0.0 0 0" />
        <axis xyz="0 1 0" />
        <limit effort="1" lower="-0.03" upper="0" velocity="1.0" />
        <dynamics damping="50" friction="1" />
    </joint>
    <!-- ///////////////////////////////////////////////////////////////////////////////////////////////////////////////////// -->
    <!-- RIGHT GRIPPER AFT LINK -->
    <link name="gripper_finger_link2">
        <visual>
            <origin xyz="0.04 0.03 0" />
            <geometry>
                <box size="0.08 0.01 0.01" />
            </geometry>
            <material name="White" />
        </visual>
        <inertial>
            <mass value="1" />
            <inertia ixx="1.0" ixy="0.0" ixz="0.0" iyy="0.5" iyz="0.0" izz="1.0" />
        </inertial>
    </link>
    <gazebo reference="gripper_finger_link2">
        <material>Gazebo/White</material>
    </gazebo>
    <!-- ///////////////////////////////////////////////////////////////////////////////////////////////////////////////////// -->
    <!-- Main sensor link -->
    <joint name="rgbd_camera_joint" type="fixed">
        <origin rpy="0.0 1.225 0.0" xyz="0.1 0.0 0.9" />
        <parent link="base_link" />
        <child link="rgbd_camera_link" />
    </joint>
    <link name="rgbd_camera_link">
        <inertial>
            <origin rpy="0 0 0" xyz="-0.00936000000 -0.00003000000 -0.00273000000" />
            <mass value="0.21970000000" />
            <inertia ixx="0.00000429247" ixy="0.00000000000" ixz="0.00000002565" iyy="0.00000008027" iyz="0.00000000000" izz="0.00000427339" />
        </inertial>
        <visual>
            <geometry>
                <mesh filename="package://a05_seven_dof_arm/meshes/sensors/xtion_pro_live/xtion_pro_live.stl" />
            </geometry>
            <material name="White" />
        </visual>
        <collision>
            <geometry>
                <mesh filename="package://a05_seven_dof_arm/meshes/sensors/xtion_pro_live/xtion_pro_live.dae" />
            </geometry>
        </collision>
    </link>
    <!-- Gazebo-specific color -->
    <gazebo reference="rgbd_camera_link">
        <material>Gazebo/White</material>
    </gazebo>
    <!-- Optical frame -->
    <joint name="rgbd_camera_optical_joint" type="fixed">
        <optical_origin rpy="-1.5750000000000002 0.0 -1.5750000000000002" xyz="0 0 0" />
        <parent link="rgbd_camera_link" />
        <child link="rgbd_camera_optical_frame" />
    </joint>
    <link name="rgbd_camera_optical_frame">
        <inertial>
            <origin rpy="0 0 0" xyz="0 0 0" />
            <mass value="0.001" />
            <inertia ixx="0.00001" ixy="0" ixz="0" iyy="0.00001" iyz="0" izz="0.00001" />
        </inertial>
    </link>
    <!-- Depth sensor frames -->
    <joint name="rgbd_camera_depth_joint" type="fixed">
        <origin rpy="0 0 0" xyz="0.0 0.049 0.0" />
        <parent link="rgbd_camera_link" />
        <child link="rgbd_camera_depth_frame" />
    </joint>
    <link name="rgbd_camera_depth_frame">
        <inertial>
            <origin rpy="0 0 0" xyz="0 0 0" />
            <mass value="0.001" />
            <inertia ixx="0.00001" ixy="0" ixz="0" iyy="0.00001" iyz="0" izz="0.00001" />
        </inertial>
    </link>
    <joint name="rgbd_camera_depth_optical_joint" type="fixed">
        <origin rpy="-1.5750000000000002 0.0 -1.5750000000000002" xyz="0 0 0" />
        <parent link="rgbd_camera_depth_frame" />
        <child link="rgbd_camera_depth_optical_frame" />
    </joint>
    <link name="rgbd_camera_depth_optical_frame">
        <inertial>
            <origin rpy="0 0 0" xyz="0 0 0" />
            <mass value="0.001" />
            <inertia ixx="0.00001" ixy="0" ixz="0" iyy="0.00001" iyz="0" izz="0.00001" />
        </inertial>
    </link>
    <!-- RGB sensor frames -->
    <joint name="rgbd_camera_rgb_joint" type="fixed">
        <origin rpy="0 0 0" xyz="0.0 0.022 0.0" />
        <parent link="rgbd_camera_link" />
        <child link="rgbd_camera_rgb_frame" />
    </joint>
    <link name="rgbd_camera_rgb_frame">
        <inertial>
            <origin rpy="0 0 0" xyz="0 0 0" />
            <mass value="0.001" />
            <inertia ixx="0.00001" ixy="0" ixz="0" iyy="0.00001" iyz="0" izz="0.00001" />
        </inertial>
    </link>
    <joint name="rgbd_camera_rgb_optical_joint" type="fixed">
        <origin rpy="-1.5750000000000002 0.0 -1.5750000000000002" xyz="0 0 0" />
        <parent link="rgbd_camera_rgb_frame" />
        <child link="rgbd_camera_rgb_optical_frame" />
    </joint>
    <link name="rgbd_camera_rgb_optical_frame">
        <inertial>
            <origin rpy="0 0 0" xyz="0 0 0" />
            <mass value="0.001" />
            <inertia ixx="0.00001" ixy="0" ixz="0" iyy="0.00001" iyz="0" izz="0.00001" />
        </inertial>
    </link>
    <gazebo reference="rgbd_camera_link">
        <!-- Depth (IR) Sensor -->
        <sensor name="rgbd_camera_depth_frame_sensor" type="depth">
            <always_on>true</always_on>
            <update_rate>6.0</update_rate>
            <camera>
                <horizontal_fov>1.0150000000000001</horizontal_fov>
                <image>
                    <format>R8G8B8</format>
                    <width>800</width>
                    <height>600</height>
                </image>
                <clip>
                    <near>0.05</near>
                    <far>1.5</far>
                </clip>
            </camera>
            <plugin filename="libgazebo_ros_openni_kinect.so" name="rgbd_camera_depth_frame_controller">
                <alwaysOn>true</alwaysOn>
                <updateRate>6.0</updateRate>
                <cameraName>rgbd_camera</cameraName>
                <imageTopicName>ir/image_raw</imageTopicName>
                <cameraInfoTopicName>ir/camera_info</cameraInfoTopicName>
                <depthImageTopicName>depth/image_raw</depthImageTopicName>
                <depthImageCameraInfoTopicName>depth/camera_info</depthImageCameraInfoTopicName>
                <pointCloudTopicName>depth/points</pointCloudTopicName>
                <frameName>rgbd_camera_optical_frame</frameName>
                <pointCloudCutoff>0.05</pointCloudCutoff>
                <pointCloudCutoffMax>5</pointCloudCutoffMax>
                <rangeMax>1.5</rangeMax>
                <!-- Distortion parameters not supported in gazebo 1.9.* plugins -->
                <!--
          <distortionK1>0.00000001</distortionK1>
          <distortionK2>0.00000001</distortionK2>
          <distortionK3>0.00000001</distortionK3>
          <distortionT1>0.00000001</distortionT1>
          <distortionT2>0.00000001</distortionT2>
          -->
            </plugin>
        </sensor>
        <!-- RGB Sensor -->
        <sensor name="rgbd_camera_rgb_frame_sensor" type="camera">
            <always_on>true</always_on>
            <update_rate>6.0</update_rate>
            <camera>
                <horizontal_fov>1.0150000000000001</horizontal_fov>
                <image>
                    <format>R8G8B8</format>
                    <width>800</width>
                    <height>600</height>
                </image>
                <clip>
                    <near>0.05</near>
                    <far>1.5</far>
                </clip>
            </camera>
            <plugin filename="libgazebo_ros_camera.so" name="rgbd_camera_rgb_frame_controller">
                <alwaysOn>true</alwaysOn>
                <updateRate>6.0</updateRate>
                <cameraName>rgbd_camera</cameraName>
                <imageTopicName>rgb/image_raw</imageTopicName>
                <cameraInfoTopicName>rgb/camera_info</cameraInfoTopicName>
                <frameName>rgbd_camera_optical_frame</frameName>
            </plugin>
        </sensor>
    </gazebo>
    <transmission name="shoulder_pan_joint_tran">
        <type>transmission_interface/SimpleTransmission</type>
        <joint name="shoulder_pan_joint">
            <hardwareInterface>hardware_interface/PositionJointInterface</hardwareInterface>
        </joint>
        <actuator name="shoulder_pan_joint_motor">
            <hardwareInterface>hardware_interface/PositionJointInterface</hardwareInterface>
            <mechanicalReduction>1</mechanicalReduction>
        </actuator>
    </transmission>
    <transmission name="shoulder_pitch_joint_tran">
        <type>transmission_interface/SimpleTransmission</type>
        <joint name="shoulder_pitch_joint">
            <hardwareInterface>hardware_interface/PositionJointInterface</hardwareInterface>
        </joint>
        <actuator name="shoulder_pitch_joint_motor">
            <hardwareInterface>hardware_interface/PositionJointInterface</hardwareInterface>
            <mechanicalReduction>1</mechanicalReduction>
        </actuator>
    </transmission>
    <transmission name="elbow_roll_joint_tran">
        <type>transmission_interface/SimpleTransmission</type>
        <joint name="elbow_roll_joint">
            <hardwareInterface>hardware_interface/PositionJointInterface</hardwareInterface>
        </joint>
        <actuator name="elbow_roll_joint_motor">
            <hardwareInterface>hardware_interface/PositionJointInterface</hardwareInterface>
            <mechanicalReduction>1</mechanicalReduction>
        </actuator>
    </transmission>
    <transmission name="elbow_pitch_joint_tran">
        <type>transmission_interface/SimpleTransmission</type>
        <joint name="elbow_pitch_joint">
            <hardwareInterface>hardware_interface/PositionJointInterface</hardwareInterface>
        </joint>
        <actuator name="elbow_pitch_joint_motor">
            <hardwareInterface>hardware_interface/PositionJointInterface</hardwareInterface>
            <mechanicalReduction>1</mechanicalReduction>
        </actuator>
    </transmission>
    <transmission name="wrist_roll_joint_tran">
        <type>transmission_interface/SimpleTransmission</type>
        <joint name="wrist_roll_joint">
            <hardwareInterface>hardware_interface/PositionJointInterface</hardwareInterface>
        </joint>
        <actuator name="wrist_roll_joint_motor">
            <hardwareInterface>hardware_interface/PositionJointInterface</hardwareInterface>
            <mechanicalReduction>1</mechanicalReduction>
        </actuator>
    </transmission>
    <transmission name="wrist_pitch_joint_tran">
        <type>transmission_interface/SimpleTransmission</type>
        <joint name="wrist_pitch_joint">
            <hardwareInterface>hardware_interface/PositionJointInterface</hardwareInterface>
        </joint>
        <actuator name="wrist_pitch_joint_motor">
            <hardwareInterface>hardware_interface/PositionJointInterface</hardwareInterface>
            <mechanicalReduction>1</mechanicalReduction>
        </actuator>
    </transmission>
    <transmission name="gripper_roll_joint_tran">
        <type>transmission_interface/SimpleTransmission</type>
        <joint name="gripper_roll_joint">
            <hardwareInterface>hardware_interface/PositionJointInterface</hardwareInterface>
        </joint>
        <actuator name="gripper_roll_joint_motor">
            <hardwareInterface>hardware_interface/PositionJointInterface</hardwareInterface>
            <mechanicalReduction>1</mechanicalReduction>
        </actuator>
    </transmission>
    <transmission name="finger_joint1_tran">
        <type>transmission_interface/SimpleTransmission</type>
        <joint name="finger_joint1">
            <hardwareInterface>hardware_interface/PositionJointInterface</hardwareInterface>
        </joint>
        <actuator name="finger_joint1_motor">
            <hardwareInterface>hardware_interface/PositionJointInterface</hardwareInterface>
            <mechanicalReduction>1</mechanicalReduction>
        </actuator>
    </transmission>
    <transmission name="finger_joint2_tran">
        <type>transmission_interface/SimpleTransmission</type>
        <joint name="finger_joint2">
            <hardwareInterface>hardware_interface/PositionJointInterface</hardwareInterface>
        </joint>
        <actuator name="finger_joint2_motor">
            <hardwareInterface>hardware_interface/PositionJointInterface</hardwareInterface>
            <mechanicalReduction>1</mechanicalReduction>
        </actuator>
    </transmission>
    <!-- ros_control plugin -->
    <gazebo>
        <plugin filename="libgazebo_ros_control.so" name="gazebo_ros_control">
            <robotNamespace>/seven_dof_arm</robotNamespace>
        </plugin>
    </gazebo>
</robot>

